Workbook
Name DL: [1]Sheet3!$B$2:$F$125

Sheet DSSV_ĐK_HƯỚNG ĐỀ TÀI
A1: TRƯỜNG ĐẠI HỌC CÔNG NGHỆ SÀI GÒN
A2: KHOA CÔNG NGHỆ THÔNG TIN
A3: DANH SÁCH SINH VIÊN - GIÁO VIÊN HƯỚNG DẪN - TÊN ĐỀ TÀI LVTN
A4: ĐẠI HỌC 2021 VÀ KHÓA CŨ LÀM LẠI
A5: NGÀNH : CÔNG NGHỆ THÔNG TIN
A7: STT | B7: MSSV | C7: HỌ TÊN SINH VIÊN | E7: LỚP | F7: SĐT | G7: Email | H7: Hướng đề tài | I7: Nhóm | J7: GVHD | K7: HH-HV | L7: Nơi công tác | M7: Tên đề tài (GVHD nhập thông tin) | N7: Nội dung tóm tắt đề tài (GVHD nhập thông tin) | O7: GHI CHÚ | P7: Kiểm dò với DS ĐKMH của P.ĐT
A8: 1 | B8: DH52002723 | C8: Phạm Ngọc | D8: Khoa | E8: D20_TH04 | F8: 0528051699 | G8: DH52002723@student.stu.edu.vn | H8: Ứng dụng trên Web | I8: 4 | J8: NGÔ XUÂN BÁCH | K8: Thạc sĩ | L8: ĐH CNSG | M8: Xây dựng Website cung dịch vụ cho thuê xe và thuê xe ô tô tự lái | N8: Tìm hiểu phương thức cung cấp dịch vụ thuê xe: điều kiện thuê, hợp đồng thuê, phương thức giao dịch… Quản lý, phân loại xe phù hợp với chủng loại, nhu cầu sử dụng, quản lý tình trạng xe, quản lý hợp đồng, thông tin khách hàng. | P8: 5 | Q8: 1 | R8: =VLOOKUP(B8,DS_ĐKMH_P.ĐT_24102025!$B$4:$J$220,2,0) -> Phạm Ngọc | S8: =VLOOKUP(B8,DS_ĐKMH_P.ĐT_24102025!$B$4:$J$220,3,0) -> Khoa | T8: =VLOOKUP(B8,DS_ĐKMH_P.ĐT_24102025!$B$4:$J$220,4,0) -> D20_TH04
A9: 2 | B9: DH52003935 | C9: Phạm Châu | D9: Phú | E9: D20_TH04 | F9: 0337847385 | G9: DH52003935@student.stu.edu.vn | H9: Ứng dụng trên Web | I9: 5 | J9: NGÔ XUÂN BÁCH | K9: Thạc sĩ | L9: ĐH CNSG | M9: Xây dựng Website bán máy tính Desktop | N9: Tìm hiểu nghiệp vụ mua bán & quản lý sản phẩm máy tính và linh kiện. Hỗ trợ tìm kiếm theo thông số kỹ thuật của sản phẩm. Theo dõi đơn hàng, kiểm tra thời hạn bảo hành sản phẩm. Hỗ trợ xây dựng cấu hình và báo giá. | P9: 6 | Q9: 2 | R9: =VLOOKUP(B9,DS_ĐKMH_P.ĐT_24102025!$B$4:$J$220,2,0) -> Phạm Châu | S9: =VLOOKUP(B9,DS_ĐKMH_P.ĐT_24102025!$B$4:$J$220,3,0) -> Phú | T9: =VLOOKUP(B9,DS_ĐKMH_P.ĐT_24102025!$B$4:$J$220,4,0) -> D20_TH04
A10: 3 | B10: DH52005870 | C10: Vũ Trung | D10: Kiên | E10: D20_TH08 | F10: 0779182032 | G10: DH52005870@student.stu.edu.vn | H10: Ứng dụng trên Web | I10: 6 | J10: NGÔ XUÂN BÁCH | K10: Thạc sĩ | L10: ĐH CNSG | M10: Xây dựng Website bán mô hình figure Nhật Bản | N10: Xây dựng website quản lý và bán sản phẩm Figure, hỗ trợ phân loại tìm kiếm theo chủ đề, chất liệu … Quản lý đơn hàng, thống kê phân loại nào được quan tâm nhiều nhất. | P10: 7 | Q10: 3 | R10: =VLOOKUP(B10,DS_ĐKMH_P.ĐT_24102025!$B$4:$J$220,2,0) -> Vũ Trung | S10: =VLOOKUP(B10,DS_ĐKMH_P.ĐT_24102025!$B$4:$J$220,3,0) -> Kiên | T10: =VLOOKUP(B10,DS_ĐKMH_P.ĐT_24102025!$B$4:$J$220,4,0) -> D20_TH08
A11: 4 | B11: DH52113174 | C11: Phạm Nguyễn Thanh | D11: Tâm | E11: D21_TH12 | F11: #N/A | G11: #N/A | H11: Ứng dụng trên Web | I11: 8 | J11: NGÔ XUÂN BÁCH | K11: Thạc sĩ | L11: ĐH CNSG | M11: Xây dựng Website hỗ trợ học tiếng Anh | N11: Tổ chức các bài học với nhiều cấp độ khác nhau. Hỗ trợ đánh giá sự tiến bộ của người học qua các bài kiểm tra, người học chỉ được tham gia bài học cấp độ cao hơn khi đạt được 80% cấp độ kế trước. | P11: 10 | Q11: 4 | R11: =VLOOKUP(B11,DS_ĐKMH_P.ĐT_24102025!$B$4:$J$220,2,0) -> Phạm Nguyễn Thanh | S11: =VLOOKUP(B11,DS_ĐKMH_P.ĐT_24102025!$B$4:$J$220,3,0) -> Tâm | T11: =VLOOKUP(B11,DS_ĐKMH_P.ĐT_24102025!$B$4:$J$220,4,0) -> D21_TH12
A12: 5 | B12: DH52106873 | C12: Nguyễn Hoàng | D12: Quan | E12: D21_TH04 | F12: #N/A | G12: #N/A | H12: Ứng dụng trên Web | I12: 9 | J12: NGÔ XUÂN BÁCH | K12: Thạc sĩ | L12: ĐH CNSG | M12: Xây dựng Website bán các sản phẩm của Apple | N12: Tìm hiểu đặc điểm sản phẩm của Apple. Hỗ trợ phân loại, tìm kiếm theo đặc điểm của sản phẩm. Theo dõi đơn hàng, kiểm tra thời hạn bảo hành sản phẩm. Thống kê doanh thu của mỗi loại sản phẩm. | P12: 11 | Q12: 5 | R12: =VLOOKUP(B12,DS_ĐKMH_P.ĐT_24102025!$B$4:$J$220,2,0) -> Nguyễn Hoàng | S12: =VLOOKUP(B12,DS_ĐKMH_P.ĐT_24102025!$B$4:$J$220,3,0) -> Quan | T12: =VLOOKUP(B12,DS_ĐKMH_P.ĐT_24102025!$B$4:$J$220,4,0) -> D21_TH04
A13: 6 | B13: DH52005699 | C13: Nguyễn Hùng | D13: Cường | E13: D20_TH10 | F13: 0932464672 | G13: DH52005699@student.stu.edu.vn | H13: * | I13: 167 | J13: NGÔ XUÂN BÁCH | K13: Thạc sĩ | L13: ĐH CNSG | M13: Xây dựng Website bán sách | N13: Tìm hiểu nghiệp vụ quản lý, phân loại sản phẩm, hỗ trợ khách hàng tìm kiếm và review một đoạn nội dung quyển sách, quản lý đơn hàng, hỗ trợ theo dõi đơn hàng, thanh toán online. | P13: 199 | Q13: 7 | R13: =VLOOKUP(B13,DS_ĐKMH_P.ĐT_24102025!$B$4:$J$220,2,0) -> Nguyễn Hùng | S13: =VLOOKUP(B13,DS_ĐKMH_P.ĐT_24102025!$B$4:$J$220,3,0) -> Cường | T13: =VLOOKUP(B13,DS_ĐKMH_P.ĐT_24102025!$B$4:$J$220,4,0) -> D20_TH10
A14: 7 | B14: DH52001024 | C14: Nguyễn Duy | D14: Sơn | E14: D20_TH02 | F14: 0783887570 | G14: DH52001024@student.stu.edu.vn | H14: * | I14: 169 | J14: NGÔ XUÂN BÁCH | K14: Thạc sĩ | L14: ĐH CNSG | M14: Xây dựng Website bán nguyên liệu sản phẩm từ thảo dược | N14: Phân loại thảo dược và dược tính của mỗi loại. Hỗ trợ tìm kiếm sản phẩm theo nhóm danh mục, công dụng. Quản lý đơn hàng, quản lý thanh toán và thống kê doanh thu, cảnh báo sản phẩm sắp hết hạn sử dụng. | Q14: 8 | R14: =VLOOKUP(B14,DS_ĐKMH_P.ĐT_24102025!$B$4:$J$220,2,0) -> Nguyễn Duy | S14: =VLOOKUP(B14,DS_ĐKMH_P.ĐT_24102025!$B$4:$J$220,3,0) -> Sơn | T14: =VLOOKUP(B14,DS_ĐKMH_P.ĐT_24102025!$B$4:$J$220,4,0) -> D20_TH02
A15: 8 | B15: DH52006188 | C15: Lê Nguyễn Trường | D15: Thịnh | E15: D20_TH10 | F15: 0774077020 | G15: DH52006188@student.stu.edu.vn | J15: NGÔ XUÂN BÁCH | K15: Thạc sĩ | L15: ĐH CNSG | M15: Xây dựng Website bán quần áo thời trang | N15: Tìm hiểu chủng loại quần áo muốn kinh doanh, hỗ trợ người dùng phân loại theo chủng loại, theo giới tính, thương hiệu... Hỗ trợ thanh toán online, theo dõi đơn hàng, thống kê doanh thu theo tháng, quý, năm và sản phẩm bán chạy nhất. | Q15: 9 | R15: =VLOOKUP(B15,DS_ĐKMH_P.ĐT_24102025!$B$4:$J$220,2,0) -> Lê Nguyễn Trường | S15: =VLOOKUP(B15,DS_ĐKMH_P.ĐT_24102025!$B$4:$J$220,3,0) -> Thịnh | T15: =VLOOKUP(B15,DS_ĐKMH_P.ĐT_24102025!$B$4:$J$220,4,0) -> D20_TH10
A16: 9 | B16: DH51900751 | C16: Ngô Tuấn | D16: Thành | E16: D19_TH06 | F16: 0777843892 | G16: DH51900751@student.stu.edu.vn | J16: NGÔ XUÂN BÁCH | K16: Thạc sĩ | L16: ĐH CNSG | M16: Xây dựng ứng dụng Web quản lý đăng ký sử dụng thiết bị phòng Gym của trường STU | N16: Quản lý thiết bị phòng gym STU, lập lịch hoạt động và cho người dùng đăng ký lịch sử dụng thiết bị. Kiểm tra đối sánh người dùng đã đăng ký lịch khi vào phòng gym và thông báo nhắc nhở người dùng nào đã hết giờ tập. | Q16: 10 | R16: =VLOOKUP(B16,DS_ĐKMH_P.ĐT_24102025!$B$4:$J$220,2,0) -> Ngô Tuấn | S16: =VLOOKUP(B16,DS_ĐKMH_P.ĐT_24102025!$B$4:$J$220,3,0) -> Thành | T16: =VLOOKUP(B16,DS_ĐKMH_P.ĐT_24102025!$B$4:$J$220,4,0) -> D19_TH06
A17: 10 | B17: DH52110693 | C17: Đỗ Ngọc Anh | D17: Duy | E17: D21_TH13 | F17: 0865006929 | G17: DH52110693@student.stu.edu.vn | H17: Ứng dụng trên Web | I17: 12 | J17: BÙI NHẬT BẰNG | K17: Thạc sĩ | L17: ĐH CNSG | M17: Xây dựng website bán quần áo | N17: Xây dựng 1 website thương mại điện tử kinh doanh quần áo | P17: 14 | Q17: 11 | R17: =VLOOKUP(B17,DS_ĐKMH_P.ĐT_24102025!$B$4:$J$220,2,0) -> Đỗ Ngọc Anh | S17: =VLOOKUP(B17,DS_ĐKMH_P.ĐT_24102025!$B$4:$J$220,3,0) -> Duy | T17: =VLOOKUP(B17,DS_ĐKMH_P.ĐT_24102025!$B$4:$J$220,4,0) -> D21_TH13
A18: 11 | B18: DH52110802 | C18: Trần Ngọc | D18: Điền | E18: D21_TH14 | F18: 0924640701 | G18: DH52110802@student.stu.edu.vn | H18: Ứng dụng trên Web | I18: 13 | J18: BÙI NHẬT BẰNG | K18: Thạc sĩ | L18: ĐH CNSG | M18: Xây dựng website mạng xã hội dành cho game thủ | N18: Xây dựng website có các chức năng cơ bản của 1 mạng xã hội hướng tới nhóm người đam mê game | P18: 15 | Q18: 12 | R18: =VLOOKUP(B18,DS_ĐKMH_P.ĐT_24102025!$B$4:$J$220,2,0) -> Trần Ngọc | S18: =VLOOKUP(B18,DS_ĐKMH_P.ĐT_24102025!$B$4:$J$220,3,0) -> Điền | T18: =VLOOKUP(B18,DS_ĐKMH_P.ĐT_24102025!$B$4:$J$220,4,0) -> D21_TH14
A19: 12 | B19: LT52200006 | C19: Trần Minh | D19: Nghĩa | E19: L22_TH01 | F19: 0908655034 | G19: LT52200006@student.stu.edu.vn | H19: Ứng dụng trên Web | I19: 20 | J19: BÙI NHẬT BẰNG | K19: Thạc sĩ | L19: ĐH CNSG | M19: Xây dựng website bán máy tính | N19: Xây dựng 1 website thương mại điện tử kinh doanh máy tính và phụ kiện | P19: 21 | Q19: 13 | R19: =VLOOKUP(B19,DS_ĐKMH_P.ĐT_24102025!$B$4:$J$220,2,0) -> Trần Minh | S19: =VLOOKUP(B19,DS_ĐKMH_P.ĐT_24102025!$B$4:$J$220,3,0) -> Nghĩa | T19: =VLOOKUP(B19,DS_ĐKMH_P.ĐT_24102025!$B$4:$J$220,4,0) -> L22_TH01
A20: 13 | B20: DH52005731 | C20: Trần Lê Minh | D20: Duy | E20: D20_TH09 | F20: 0838567807 | G20: DH52005731@student.stu.edu.vn | H20: Ứng dụng trên Web | I20: 15 | J20: BÙI NHẬT BẰNG | K20: Thạc sĩ | L20: ĐH CNSG | M20: Xây dựng website bán quần áo | N20: Xây dựng 1 website thương mại điện tử kinh doanh quần áo | P20: 17 | Q20: 15 | R20: =VLOOKUP(B20,DS_ĐKMH_P.ĐT_24102025!$B$4:$J$220,2,0) -> Trần Lê Minh | S20: =VLOOKUP(B20,DS_ĐKMH_P.ĐT_24102025!$B$4:$J$220,3,0) -> Duy | T20: =VLOOKUP(B20,DS_ĐKMH_P.ĐT_24102025!$B$4:$J$220,4,0) -> D20_TH09
A21: 14 | B21: DH52002303 | C21: Lê Chí | D21: Cường | E21: D20_TH01 | F21: 0904446653 | G21: DH52002303@student.stu.edu.vn | H21: Ứng dụng trên Web | I21: 28 | J21: BÙI NHẬT BẰNG | K21: Thạc sĩ | L21: ĐH CNSG | M21: Xây dựng website thương mại điện tử cho công ty OLDTOT | N21: Xây dựng website cho phép người dùng rao bán hoặc tặng đồ cũ, người mua có thể tìm và liên hệ với người bán hoặc người tặng | P21: 31 | Q21: 16 | R21: =VLOOKUP(B21,DS_ĐKMH_P.ĐT_24102025!$B$4:$J$220,2,0) -> Lê Chí | S21: =VLOOKUP(B21,DS_ĐKMH_P.ĐT_24102025!$B$4:$J$220,3,0) -> Cường | T21: =VLOOKUP(B21,DS_ĐKMH_P.ĐT_24102025!$B$4:$J$220,4,0) -> D20_TH01
A22: 15 | B22: DH52002302 | C22: Cao Hoàng | D22: Nam | E22: D20_TH01 | F22: 0909393047 | G22: DH52002302@student.stu.edu.vn | H22: Ứng dụng trên Web | I22: 28 | J22: BÙI NHẬT BẰNG | K22: Thạc sĩ | L22: ĐH CNSG | P22: 32 | Q22: 17 | R22: =VLOOKUP(B22,DS_ĐKMH_P.ĐT_24102025!$B$4:$J$220,2,0) -> Cao Hoàng | S22: =VLOOKUP(B22,DS_ĐKMH_P.ĐT_24102025!$B$4:$J$220,3,0) -> Nam | T22: =VLOOKUP(B22,DS_ĐKMH_P.ĐT_24102025!$B$4:$J$220,4,0) -> D20_TH01
A23: 16 | B23: DH52110995 | C23: Đỗ Quang | D23: Huy | E23: D21_TH09 | F23: 0395553134 | G23: DH52110995@student.stu.edu.vn | H23: * | I23: 170 | J23: BÙI NHẬT BẰNG | K23: Thạc sĩ | L23: ĐH CNSG | M23: Xây dựng website đặt vé xem phim cho công ty CINEGO | N23: Xây dựng 1 website cho phép người dùng đặt vé xem phim, tìm kiếm phim cần mua vé, thanh toán online | Q23: 19 | R23: =VLOOKUP(B23,DS_ĐKMH_P.ĐT_24102025!$B$4:$J$220,2,0) -> Đỗ Quang | S23: =VLOOKUP(B23,DS_ĐKMH_P.ĐT_24102025!$B$4:$J$220,3,0) -> Huy | T23: =VLOOKUP(B23,DS_ĐKMH_P.ĐT_24102025!$B$4:$J$220,4,0) -> D21_TH09
A24: 17 | B24: DH52111083 | C24: Trần Mai Huy | D24: Khải | E24: D21_TH09 | F24: 0582079957 | G24: DH52111083@student.stu.edu.vn | H24: * | I24: 171 | J24: BÙI NHẬT BẰNG | K24: Thạc sĩ | L24: ĐH CNSG | Q24: 20 | R24: =VLOOKUP(B24,DS_ĐKMH_P.ĐT_24102025!$B$4:$J$220,2,0) -> Trần Mai Huy | S24: =VLOOKUP(B24,DS_ĐKMH_P.ĐT_24102025!$B$4:$J$220,3,0) -> Khải | T24: =VLOOKUP(B24,DS_ĐKMH_P.ĐT_24102025!$B$4:$J$220,4,0) -> D21_TH09
A25: 18 | B25: DH52110660 | C25: Nguyễn Chí | D25: Cường | E25: D21_TH05 | F25: 0901315352 | G25: DH52110660@student.stu.edu.vn | J25: BÙI NHẬT BẰNG | K25: Thạc sĩ | L25: ĐH CNSG | M25: Xây dựng mạng xã hội kết nối hoạt động cộng đồng | N25: Xây dựng mạng xã hội chuyên về các hoạt động cộng đồng: đăng sự kiện, đăng ký tham gia, chia sẻ thông tin sự kiện với người khác | Q25: 21 | R25: =VLOOKUP(B25,DS_ĐKMH_P.ĐT_24102025!$B$4:$J$220,2,0) -> Nguyễn Chí | S25: =VLOOKUP(B25,DS_ĐKMH_P.ĐT_24102025!$B$4:$J$220,3,0) -> Cường | T25: =VLOOKUP(B25,DS_ĐKMH_P.ĐT_24102025!$B$4:$J$220,4,0) -> D21_TH05
A26: 19 | B26: DH52003995 | C26: Huỳnh Thanh | D26: Phúc | E26: D20_TH04 | F26: 0348095507 | G26: DH52003995@student.stu.edu.vn | H26: Ứng dụng trên Web | I26: 16 | J26: ĐOÀN TRÌNH DỤC | K26: Thạc sĩ | L26: ĐH CNSG | M26: Quản Lý quán cafe | N26: Xây dựng website + app hỗ trợ đặt món thanh toán cho quán cafe | P26: 18 | Q26: 22 | R26: =VLOOKUP(B26,DS_ĐKMH_P.ĐT_24102025!$B$4:$J$220,2,0) -> Huỳnh Thanh | S26: =VLOOKUP(B26,DS_ĐKMH_P.ĐT_24102025!$B$4:$J$220,3,0) -> Phúc | T26: =VLOOKUP(B26,DS_ĐKMH_P.ĐT_24102025!$B$4:$J$220,4,0) -> D20_TH04
A27: 20 | B27: DH52001281 | C27: Phạm Tôn | D27: Thuận | E27: D20-TH04 | F27: #N/A | G27: #N/A | H27: Ứng dụng trên Web | I27: 17 | J27: ĐOÀN TRÌNH DỤC | K27: Thạc sĩ | L27: ĐH CNSG | M27: Website ôn thi trắc nghiệm | N27: hỗ trợ người dùng quản lý và ôn thi trắc nghiệm | P27: 19 | Q27: 23 | R27: =VLOOKUP(B27,DS_ĐKMH_P.ĐT_24102025!$B$4:$J$220,2,0) -> Phạm Tôn | S27: =VLOOKUP(B27,DS_ĐKMH_P.ĐT_24102025!$B$4:$J$220,3,0) -> Thuận | T27: =VLOOKUP(B27,DS_ĐKMH_P.ĐT_24102025!$B$4:$J$220,4,0) -> D20_TH04
A28: 21 | B28: DH52111212 | C28: Nguyễn Hoàng | D28: Linh | E28: D21_TH11 | F28: 0941412077 | G28: DH52111212@student.stu.edu.vn | H28: Ứng dụng trên Mobile | I28: 25 | J28: ĐOÀN TRÌNH DỤC | K28: Thạc sĩ | L28: ĐH CNSG | M28: Website hỗ trợ chia sẻ tài liệu sử dụng công nghệ NFT | N28: Website hỗ trợ chia sẻ tài liệu sử dụng công nghệ NFT | P28: 27 | Q28: 24 | R28: =VLOOKUP(B28,DS_ĐKMH_P.ĐT_24102025!$B$4:$J$220,2,0) -> Nguyễn Hoàng | S28: =VLOOKUP(B28,DS_ĐKMH_P.ĐT_24102025!$B$4:$J$220,3,0) -> Linh | T28: =VLOOKUP(B28,DS_ĐKMH_P.ĐT_24102025!$B$4:$J$220,4,0) -> D21_TH11
A29: 22 | B29: DH52111579 | C29: Nguyễn Việt | D29: Phương | E29: D21_TH09 | F29: 0978699529 | G29: DH52111579@student.stu.edu.vn | H29: Ứng dụng trên Web | I29: 56 | J29: ĐOÀN TRÌNH DỤC | K29: Thạc sĩ | L29: ĐH CNSG | M29: Website hỗ trợ tìm kiếm việc làm | N29: Website hỗ trợ tìm kiếm việc làm | P29: 66 | Q29: 25 | R29: =VLOOKUP(B29,DS_ĐKMH_P.ĐT_24102025!$B$4:$J$220,2,0) -> Nguyễn Việt | S29: =VLOOKUP(B29,DS_ĐKMH_P.ĐT_24102025!$B$4:$J$220,3,0) -> Phương | T29: =VLOOKUP(B29,DS_ĐKMH_P.ĐT_24102025!$B$4:$J$220,4,0) -> D21_TH09
A30: 23 | B30: DH52111486 | C30: Nguyễn Tấn | D30: Phi | E30: D21_TH09 | F30: 0703760626 | G30: DH52111486@student.stu.edu.vn | H30: Ứng dụng trên Web | I30: 56 | J30: ĐOÀN TRÌNH DỤC | K30: Thạc sĩ | L30: ĐH CNSG | M30: Website quản lý sân bóng | N30: Website quản lý sân bóng | P30: 68 | Q30: 26 | R30: =VLOOKUP(B30,DS_ĐKMH_P.ĐT_24102025!$B$4:$J$220,2,0) -> Nguyễn Tấn | S30: =VLOOKUP(B30,DS_ĐKMH_P.ĐT_24102025!$B$4:$J$220,3,0) -> Phi | T30: =VLOOKUP(B30,DS_ĐKMH_P.ĐT_24102025!$B$4:$J$220,4,0) -> D21_TH09
A31: 24 | B31: DH52106740 | C31: Trần Hoàng | D31: Long | E31: D21_TH03 | F31: #N/A | G31: #N/A | H31: Ứng dụng trên Mobile | I31: 92 | J31: ĐOÀN TRÌNH DỤC | K31: Thạc sĩ | L31: ĐH CNSG | M31: Ứng dụng + website hỗ trợ đấu giá sử dụng blockchain | N31: Ứng dụng + website hỗ trợ đấu giá sử dụng blockchain | O31: ĐKMH BS | P31: 111 | Q31: 27 | R31: =VLOOKUP(B31,DS_ĐKMH_P.ĐT_24102025!$B$4:$J$220,2,0) -> #N/A | S31: =VLOOKUP(B31,DS_ĐKMH_P.ĐT_24102025!$B$4:$J$220,3,0) -> #N/A | T31: =VLOOKUP(B31,DS_ĐKMH_P.ĐT_24102025!$B$4:$J$220,4,0) -> #N/A
A32: 25 | B32: DH52106130 | C32: Bùi Phi | D32: Hùng | E32: D21_TH01 | F32: 0394126389 | G32: DH52106130@student.stu.edu.vn | H32: Ứng dụng trên Mobile | I32: 98 | J32: ĐOÀN TRÌNH DỤC | K32: Thạc sĩ | L32: ĐH CNSG | M32: Ứng dụng quản lý tập lluyện và chế độ ăn cá nhân | N32: Ứng dụng quản lý tập lluyện và chế độ ăn cá nhân | P32: 119 | Q32: 28 | R32: =VLOOKUP(B32,DS_ĐKMH_P.ĐT_24102025!$B$4:$J$220,2,0) -> Bùi Phi | S32: =VLOOKUP(B32,DS_ĐKMH_P.ĐT_24102025!$B$4:$J$220,3,0) -> Hùng | T32: =VLOOKUP(B32,DS_ĐKMH_P.ĐT_24102025!$B$4:$J$220,4,0) -> D21_TH01
A33: 26 | B33: DH52111240 | C33: Nguyễn Viết | D33: Long | E33: D21_TH08 | F33: #N/A | G33: #N/A | H33: Ứng dụng trên Mobile | I33: 101 | J33: ĐOÀN TRÌNH DỤC | K33: Thạc sĩ | L33: ĐH CNSG | M33: Ứng dụng đọc truyện tranh manga | N33: Mô tả: xây dựng backend và frontend di động hỗ trợ đọc truyện online | P33: 122 | Q33: 29 | R33: =VLOOKUP(B33,DS_ĐKMH_P.ĐT_24102025!$B$4:$J$220,2,0) -> Nguyễn Viết | S33: =VLOOKUP(B33,DS_ĐKMH_P.ĐT_24102025!$B$4:$J$220,3,0) -> Long | T33: =VLOOKUP(B33,DS_ĐKMH_P.ĐT_24102025!$B$4:$J$220,4,0) -> D21_TH08
A34: 27 | B34: DH52110733 | C34: Nguyễn Sơn | D34: Dương | E34: D21_TH11 | F34: 0826464186 | G34: DH52110733@student.stu.edu.vn | H34: Ứng dụng trên Mobile | I34: 107 | J34: ĐOÀN TRÌNH DỤC | K34: Thạc sĩ | L34: ĐH CNSG | M34: Ứng dụng hỗ trợ chạy bộ sử dụng công nghệ NFT | N34: Ứng dụng hỗ trợ chạy bộ sử dụng công nghệ NFT | P34: 129 | Q34: 30 | R34: =VLOOKUP(B34,DS_ĐKMH_P.ĐT_24102025!$B$4:$J$220,2,0) -> Nguyễn Sơn | S34: =VLOOKUP(B34,DS_ĐKMH_P.ĐT_24102025!$B$4:$J$220,3,0) -> Dương | T34: =VLOOKUP(B34,DS_ĐKMH_P.ĐT_24102025!$B$4:$J$220,4,0) -> D21_TH11
A35: 28 | B35: DH52005851 | C35: Nguyễn Tấn | D35: Huy | E35: D20_TH08 | F35: 0919202108 | G35: DH52005851@student.stu.edu.vn | H35: * | I35: 172 | J35: ĐOÀN TRÌNH DỤC | K35: Thạc sĩ | L35: ĐH CNSG | M35: Công cụ/bot hỗ trợ giao dịch sàn binance | Q35: 72 | R35: =VLOOKUP(B35,DS_ĐKMH_P.ĐT_24102025!$B$4:$J$220,2,0) -> Nguyễn Tấn | S35: =VLOOKUP(B35,DS_ĐKMH_P.ĐT_24102025!$B$4:$J$220,3,0) -> Huy | T35: =VLOOKUP(B35,DS_ĐKMH_P.ĐT_24102025!$B$4:$J$220,4,0) -> D20_TH08
A36: 29 | B36: DH52113345 | C36: Lữ Mai | D36: Phương | E36: D21_TH08 | F36: 0833063875 | G36: DH52113345@student.stu.edu.vn | H36: * | I36: 179 | J36: ĐOÀN TRÌNH DỤC | K36: Thạc sĩ | L36: ĐH CNSG | M36: Phát hiện tấn công DDOS bằng học sâu trên dữ liệu NetFlow | N36: Phát hiện tấn công DDOS bằng học sâu trên dữ liệu NetFlow | Q36: 202 | R36: =VLOOKUP(B36,DS_ĐKMH_P.ĐT_24102025!$B$4:$J$220,2,0) -> Lữ Mai | S36: =VLOOKUP(B36,DS_ĐKMH_P.ĐT_24102025!$B$4:$J$220,3,0) -> Phương | T36: =VLOOKUP(B36,DS_ĐKMH_P.ĐT_24102025!$B$4:$J$220,4,0) -> D21_TH08
A37: 30 | B37: DH52111171 | C37: Lâm Tuấn | D37: Kiệt | E37: D21_TH10 | F37: 0941693505 | G37: DH52111171@student.stu.edu.vn | H37: Ứng dụng trên Web | I37: 2 | J37: LÊ THỊ MỸ DUNG | K37: Thạc sĩ | L37: ĐH CNSG | M37: Xây dựng webiste bán điện thoại di động | N37: Sinh viên tìm hiểu nghiệp vụ và phân tích, thiết kế xây dựng website bán điện thoại di động | P37: 2 | Q37: 32 | R37: =VLOOKUP(B37,DS_ĐKMH_P.ĐT_24102025!$B$4:$J$220,2,0) -> Lâm Tuấn | S37: =VLOOKUP(B37,DS_ĐKMH_P.ĐT_24102025!$B$4:$J$220,3,0) -> Kiệt | T37: =VLOOKUP(B37,DS_ĐKMH_P.ĐT_24102025!$B$4:$J$220,4,0) -> D21_TH10
A38: 31 | B38: DH52112019 | C38: Nguyễn Ngọc Thanh | D38: Tuệ | E38: D21_TH08 | F38: 0907355548 | G38: DH52112019@student.stu.edu.vn | H38: Ứng dụng trên Web | I38: 24 | J38: LÊ THỊ MỸ DUNG | K38: Thạc sĩ | L38: ĐH CNSG | M38: Xây dựng website Bán cây cảnh | N38: Sinh viên tìm hiểu nghiệp vụ và phân tích, thiết kế xây dựng website bán cây cảnh | P38: 26 | Q38: 35 | R38: =VLOOKUP(B38,DS_ĐKMH_P.ĐT_24102025!$B$4:$J$220,2,0) -> Nguyễn Ngọc Thanh | S38: =VLOOKUP(B38,DS_ĐKMH_P.ĐT_24102025!$B$4:$J$220,3,0) -> Tuệ | T38: =VLOOKUP(B38,DS_ĐKMH_P.ĐT_24102025!$B$4:$J$220,4,0) -> D21_TH08
A39: 32 | B39: DH52111085 | C39: Trương Minh | D39: Khải | E39: D21_TH08 | F39: 0835359010 | G39: DH52111085@student.stu.edu.vn | H39: Ứng dụng trên Web | I39: 49 | J39: LÊ THỊ MỸ DUNG | K39: Thạc sĩ | L39: ĐH CNSG | M39: Xây dựng website Quản lý đặt phòng và dịch vụ cho Khách sạn | N39: Sinh viên tìm hiểu nghiệp vụ và phân tích, thiết kế xây dựng website đặt phòng và dịch vụ của Khách sạn | P39: 58 | Q39: 36 | R39: =VLOOKUP(B39,DS_ĐKMH_P.ĐT_24102025!$B$4:$J$220,2,0) -> Trương Minh | S39: =VLOOKUP(B39,DS_ĐKMH_P.ĐT_24102025!$B$4:$J$220,3,0) -> Khải | T39: =VLOOKUP(B39,DS_ĐKMH_P.ĐT_24102025!$B$4:$J$220,4,0) -> D21_TH08
A40: 33 | B40: DH52000682 | C40: Lê | D40: Tuấn | E40: D20_TH03 | F40: 0777789336 | G40: DH52000682@student.stu.edu.vn | H40: Ứng dụng trên Web | I40: 61 | J40: TRỊNH THANH DUY | K40: Thạc sĩ | L40: ĐH CNSG | M40: Xây dựng website bán giày | N40: Tìm hiểu nghiệp vụ bán giày của các website bán giày hiện có Xây dựng quy trình nghiệp vụ, lược đồ CSDL, thiết kế giao diện cho đề tài Xây dựng website bán giày theo quy trình đã thiết kế | P40: 73 | Q40: 37 | R40: =VLOOKUP(B40,DS_ĐKMH_P.ĐT_24102025!$B$4:$J$220,2,0) -> Lê | S40: =VLOOKUP(B40,DS_ĐKMH_P.ĐT_24102025!$B$4:$J$220,3,0) -> Tuấn | T40: =VLOOKUP(B40,DS_ĐKMH_P.ĐT_24102025!$B$4:$J$220,4,0) -> D20_TH03
A41: 34 | B41: DH52001330 | C41: Phạm Ngọc | D41: Đông | E41: D20_TH03 | F41: 0366468307 | G41: DH52001330@student.stu.edu.vn | H41: Ứng dụng trên Web | I41: 61 | J41: TRỊNH THANH DUY | K41: Thạc sĩ | L41: ĐH CNSG | P41: 74 | Q41: 38 | R41: =VLOOKUP(B41,DS_ĐKMH_P.ĐT_24102025!$B$4:$J$220,2,0) -> Phạm Ngọc | S41: =VLOOKUP(B41,DS_ĐKMH_P.ĐT_24102025!$B$4:$J$220,3,0) -> Đông | T41: =VLOOKUP(B41,DS_ĐKMH_P.ĐT_24102025!$B$4:$J$220,4,0) -> D20_TH03
...

Sheet SVĐK_TheoLink
A1: Timestamp | B1: Email Address | C1: Họ và tên sinh viên 1 | D1: Lớp sinh viên 1 | E1: Mã sinh viên 1 | F1: Số điện thoại sinh viên 1 | G1: Số Nhóm | H1: Có làm chung nhóm với sinh viên khác không?
A2: 45919.487 | B2: dh52111445@student.stu.edu.vn | C2: Lê Trần Ngọc Như | D2: D21_TH09 | E2: DH52111445 | F2: 347846586 | G2: 1 | H2: Ứng dụng trên Web
A3: 45919.503 | B3: dh52111171@student.stu.edu.vn | C3: Lâm Tuấn Kiệt | D3: D21_TH10 | E3: DH52111171 | F3: 941693505 | G3: 2 | H3: Ứng dụng trên Web
A4: 45919.773 | B4: dh52111143@student.stu.edu.vn | C4: Nguyễn Lê Quốc Khoa | D4: D21_TH10 | E4: DH52111143 | F4: 706718920 | G4: 3 | H4: Ứng dụng trên Web
C5: Nguyễn Trần Minh Khánh | D5: D21_TH10 | E5: DH52111118 | F5: 934683146 | G5: 3
A6: 45919.511 | B6: dh52002723@student.stu.edu.vn | C6: Phạm Ngọc Khoa | D6: D20_TH04 | E6: DH52002723 | F6: 528051699 | G6: 4 | H6: Ứng dụng trên Web
A7: 45919.512 | B7: dh52003935@student.stu.edu.vn | C7: Phạm Châu Phú | D7: D20_TH04 | E7: DH52003935 | F7: 337847385 | G7: 5 | H7: Ứng dụng trên Web
A8: 45919.512 | B8: dh52005870@student.stu.edu.vn | C8: Vũ Trung Kiên | D8: D20_TH08 | E8: DH52005870 | F8: 779182032 | G8: 6 | H8: Ứng dụng trên Web
A9: 45919.529 | B9: dh52111700@student.stu.edu.vn | C9: Thái Tấn Tài | D9: D21_TH09 | E9: DH52111700 | F9: 353004163 | G9: 7 | H9: Ứng dụng trên Web
C10: Nguyễn Thị Minh Thư | D10: D21_TH10 | E10: DH52111863 | F10: 393214927 | G10: 7
A11: 45919.529 | B11: dh52113174@student.stu.edu.vn | C11: Phạm Nguyễn Thanh Tâm | D11: D21_TH12 | E11: DH52113174 | F11: 853705780 | G11: 8 | H11: Ứng dụng trên Web
A12: 45919.531 | B12: dh52106873@student.stu.edu.vn | C12: Nguyễn Hoàng Quan | D12: D21_TH04 | E12: DH52106873 | F12: 777727616 | G12: 9 | H12: Ứng dụng trên Web
A13: 45924.032 | B13: dh52110581@student.stu.edu.vn | C13: Nguyễn ngọc ân | D13: D21_TH13 | E13: DH52110581 | F13: 921266924 | G13: 10 | H13: Ứng dụng trên Web
A14: 45919.534 | B14: dh52111036@student.stu.edu.vn | C14: Nguyễn Xuân Huy | D14: D21_TH11 | E14: DH52111036 | F14: 38712230 | G14: 11 | H14: Ứng dụng trên Web
A15: 45919.535 | B15: dh52110693@student.stu.edu.vn | C15: Đỗ Ngọc Anh Duy | D15: D21_TH13 | E15: DH52110693 | F15: 865006929 | G15: 12 | H15: Ứng dụng trên Web
A16: 45919.545 | B16: dh52110802@student.stu.edu.vn | C16: Trần Ngọc Điền | D16: D21_TH14 | E16: DH52110802 | F16: 374215915 | G16: 13 | H16: Ứng dụng trên Web
A17: 45919.546 | B17: dh52110561@student.stu.edu.vn | C17: Nguyễn Lan Anh | D17: D21_TH11 | E17: DH52110561 | F17: 329186138 | G17: 14 | H17: Ứng dụng trên Mobile
A18: 45919.547 | B18: dh52005731@student.stu.edu.vn | C18: Trần Lê Minh Duy | D18: D20_TH09 | E18: DH52005731 | F18: 838567807 | G18: 15 | H18: Ứng dụng trên Web
A19: 45919.547 | B19: dh52003995@student.stu.edu.vn | C19: Huỳnh Thanh Phúc | D19: D20_TH04 | E19: DH52003995 | F19: 348095507 | G19: 16 | H19: Ứng dụng trên Web
A20: 45919.548 | B20: dh52001281@student.stu.edu.vn | C20: Phạm Tôn Thuận | D20: D20-TH04 | E20: DH52001281 | F20: 902827377 | G20: 17 | H20: Ứng dụng trên Web
A21: 45919.551 | B21: dh52105346@student.stu.edu.vn | C21: Lê Nguyễn Thành Vũ | D21: D21_TH02 | E21: DH52105346 | F21: 763163435 | G21: 19 | H21: Ứng dụng .Net
A22: 45919.553 | B22: lt52200006@student.stu.edu.vn | C22: Trần Minh Nghĩa | D22: L22_TH01 | E22: LT52200006 | F22: 706287664 | G22: 20 | H22: Ứng dụng trên Web
... A25: 45919.565 | B25: dh52111833@student.stu.edu.vn | C25: Lê Nguyễn Minh Thông | D25: D21_TH08 | E25: DH52111833 | F25: 769630210 | G25: 23 | H25: Ứng dụng trên Mobile
C26: Võ Hoàng Phúc | D26: D21_TH08 | E26: DH52111560 | F26: 767764470 | G26: 23
A27: 45919.57 | B27: dh52112019@student.stu.edu.vn | C27: NGUYỄN NGỌC THANH TUỆ | D27: D21_TH08 | E27: DH52112019 | F27: 937863453 | G27: 24 | H27: Ứng dụng trên Web
A28: 45919.574 | B28: dh52111212@student.stu.edu.vn | C28: Nguyễn Hoàng Linh | D28: D21_TH11 | E28: DH52111212 | F28: 941412077 | G28: 25 | H28: Ứng dụng trên Mobile
A29: 45919.575 | B29: dh52112786@student.stu.edu.vn | C29: Đinh Quang Thịnh | D29: D21_TH10 | E29: DH52112786 | F29: 931487603 | G29: 26 | H29: Ứng dụng trên Mobile
A30: 45919.581 | B30: dh52111881@student.stu.edu.vn | C30: Trần Thủy Tiên | D30: D21_TH08 | E30: DH52111881 | F30: 327458490 | G30: 27 | H30: Ứng dụng trên Web
C31: Đoàn Thị Yến Bình | D31: D21_TH06 | E31: DH52108380 | F31: 965687352 | G31: 27
A32: 45919.617 | B32: dh52002303@student.stu.edu.vn | C32: Lê Chí Cường | D32: D20_TH01 | E32: DH52002303 | F32: 904446653 | G32: 28 | H32: Ứng dụng trên Web
C33: Cao Hoàng Nam | D33: D20_TH01 | E33: DH52002302 | F33: 909393047 | G33: 28
A34: 45919.632 | B34: dh52111681@student.stu.edu.vn | C34: Lê Anh Tài | D34: D21_TH10 | E34: DH52111681 | F34: 967788246 | G34: 29 | H34: Ứng dụng trên Mobile
A35: 45919.663 | B35: dh52111067@student.stu.edu.vn | C35: Trần Minh Hưng | D35: D21_TH11 | E35: DH52111067 | F35: 879682202 | G35: 30 | H35: Ứng dụng trên Mobile
A36: 45919.668 | B36: dh52007186@student.stu.edu.vn | C36: Trần Như Nguyện | D36: D20_TH10 | E36: DH52007186 | F36: 388065951 | G36: 31 | H36: Ứng dụng trên Web
C37: Lưu Thị Thanh Thảo | D37: D20_TH06 | E37: DH52004272 | F37: 329824880 | G37: 31
A38: 45919.672 | B38: dh52001037@student.stu.edu.vn | C38: Lê Trung Nam | D38: D20_TH01 | E38: DH52001037 | F38: 559015966 | G38: 32 | H38: Ứng dụng trên Web
A39: 45919.693 | B39: dh52111401@student.stu.edu.vn | C39: Lê Quang Nhân | D39: D21_TH08 | E39: DH52111401 | F39: 337570400 | G39: 33 | H39: Ứng dụng trên Web
A40: 45919.707 | B40: dh52113292@student.stu.edu.vn | C40: Lê Minh Kiệt | D40: D21_TH08 | E40: Dh52113292 | F40: 327733661 | G40: 34 | H40: Ứng dụng trên Web
C41: Trần Trọng Nhân | D41: D21_TH08 | E41: DH52111411 | F41: 334554423 | G41: 34
A42: 45924.713 | B42: dh52104425@student.stu.edu.vn | C42: Nguyễn Thị Nhung | D42: D21_TH09 | E42: DH52111441 | F42: 354219578 | G42: 35 | H42: Ứng dụng trên Web
...

Sheet DS_ĐKMH_P.ĐT_24102025
A1: DANH SÁCH SINH VIÊN ĐĂNG KÝ MÔN HỌC ĐỒ ÁN / KHÓA LUẬN TỐT NGHIỆP HK1 (25 - 26)
B2: Dữ liệu đăng ký được tính đến ngày 07/10/2025
A3: STT | B3: MASV | C3: HỌ VÀ TÊN | E3: LỚP | F3: MAMH | G3: TÊN MÔN HỌC | H3: SỐ ĐIỆN THOẠI | I3: EMAIL | J3: GHI CHÚ
A4: 1 | B4: DH51801379 | C4: Ngô Minh | D4: Đạt | E4: D18_TH01 | F4: CS03153 | G4: Đồ án / Khóa luận tốt nghiệp | H4: 0792170819 | I4: =B4&"@student.stu.edu.vn" -> DH51801379@student.stu.edu.vn | K4: =VLOOKUP(B4,'DSSV_ĐK_HƯỚNG ĐỀ TÀI'!$B$8:$O$208,2,0) -> Ngô Minh | L4: =VLOOKUP(B4,'DSSV_ĐK_HƯỚNG ĐỀ TÀI'!$B$8:$O$208,3,0) -> Đạt
A5: 2 | B5: DH51904876 | C5: Trần Đông | D5: Vi | E5: D19_TH02 | F5: CS03153 | G5: Đồ án / Khóa luận tốt nghiệp | H5: 0846941020 | I5: =B5&"@student.stu.edu.vn" -> DH51904876@student.stu.edu.vn | K5: =VLOOKUP(B5,'DSSV_ĐK_HƯỚNG ĐỀ TÀI'!$B$8:$O$208,2,0) -> Trần Đông | L5: =VLOOKUP(B5,'DSSV_ĐK_HƯỚNG ĐỀ TÀI'!$B$8:$O$208,3,0) -> Vi
A6: 3 | B6: DH51903427 | C6: Lương Ngọc Hải | D6: Đăng | E6: D19_TH04 | F6: CS03153 | G6: Đồ án / Khóa luận tốt nghiệp | H6: 0847846688 | I6: =B6&"@student.stu.edu.vn" -> DH51903427@student.stu.edu.vn | K6: =VLOOKUP(B6,'DSSV_ĐK_HƯỚNG ĐỀ TÀI'!$B$8:$O$208,2,0) -> Lương Ngọc Hải | L6: =VLOOKUP(B6,'DSSV_ĐK_HƯỚNG ĐỀ TÀI'!$B$8:$O$208,3,0) -> Đăng
A7: 4 | B7: DH51904163 | C7: Nguyễn Hoàng Yến | D7: Nhi | E7: D19_TH04 | F7: CS03153 | G7: Đồ án / Khóa luận tốt nghiệp | H7: 0908127858 | I7: =B7&"@student.stu.edu.vn" -> DH51904163@student.stu.edu.vn | K7: =VLOOKUP(B7,'DSSV_ĐK_HƯỚNG ĐỀ TÀI'!$B$8:$O$208,2,0) -> Nguyễn Hoàng Yến | L7: =VLOOKUP(B7,'DSSV_ĐK_HƯỚNG ĐỀ TÀI'!$B$8:$O$208,3,0) -> Nhi
A8: 5 | B8: DH51904209 | C8: Nguyễn Thị Hồng | D8: Oanh | E8: D19_TH04 | F8: CS03153 | G8: Đồ án / Khóa luận tốt nghiệp | H8: 0857649997 | I8: =B8&"@student.stu.edu.vn" -> DH51904209@student.stu.edu.vn | K8: =VLOOKUP(B8,'DSSV_ĐK_HƯỚNG ĐỀ TÀI'!$B$8:$O$208,2,0) -> Nguyễn Thị Hồng | L8: =VLOOKUP(B8,'DSSV_ĐK_HƯỚNG ĐỀ TÀI'!$B$8:$O$208,3,0) -> Oanh
A9: 6 | B9: DH51901588 | C9: Trần Thanh | D9: Duy | E9: D19_TH05 | F9: CS03153 | G9: Đồ án / Khóa luận tốt nghiệp | H9: 0382298651 | I9: =B9&"@student.stu.edu.vn" -> DH51901588@student.stu.edu.vn | K9: =VLOOKUP(B9,'DSSV_ĐK_HƯỚNG ĐỀ TÀI'!$B$8:$O$208,2,0) -> Trần Thanh | L9: =VLOOKUP(B9,'DSSV_ĐK_HƯỚNG ĐỀ TÀI'!$B$8:$O$208,3,0) -> Duy
A10: 7 | B10: DH51903563 | C10: Hình Tân | D10: Hiệp | E10: D19_TH05 | F10: CS03153 | G10: Đồ án / Khóa luận tốt nghiệp | H10: 0966492994 | I10: =B10&"@student.stu.edu.vn" -> DH51903563@student.stu.edu.vn | K10: =VLOOKUP(B10,'DSSV_ĐK_HƯỚNG ĐỀ TÀI'!$B$8:$O$208,2,0) -> Hình Tân | L10: =VLOOKUP(B10,'DSSV_ĐK_HƯỚNG ĐỀ TÀI'!$B$8:$O$208,3,0) -> Hiệp
A11: 8 | B11: DH51905046 | C11: Kha Trí | D11: Hùng | E11: D19_TH05 | F11: CS03153 | G11: Đồ án / Khóa luận tốt nghiệp | H11: 0356065109 | I11: =B11&"@student.stu.edu.vn" -> DH51905046@student.stu.edu.vn | K11: =VLOOKUP(B11,'DSSV_ĐK_HƯỚNG ĐỀ TÀI'!$B$8:$O$208,2,0) -> Kha Trí | L11: =VLOOKUP(B11,'DSSV_ĐK_HƯỚNG ĐỀ TÀI'!$B$8:$O$208,3,0) -> Hùng
A12: 9 | B12: DH51904519 | C12: Ngô Định | D12: Thế | E12: D19_TH05 | F12: CS03153 | G12: Đồ án / Khóa luận tốt nghiệp | H12: 0347473674 | I12: =B12&"@student.stu.edu.vn" -> DH51904519@student.stu.edu.vn | K12: =VLOOKUP(B12,'DSSV_ĐK_HƯỚNG ĐỀ TÀI'!$B$8:$O$208,2,0) -> Ngô Định | L12: =VLOOKUP(B12,'DSSV_ĐK_HƯỚNG ĐỀ TÀI'!$B$8:$O$208,3,0) -> Thế
A13: 10 | B13: DH51900751 | C13: Ngô Tuấn | D13: Thành | E13: D19_TH06 | F13: CS03153 | G13: Đồ án / Khóa luận tốt nghiệp | H13: 0777843892 | I13: =B13&"@student.stu.edu.vn" -> DH51900751@student.stu.edu.vn | K13: =VLOOKUP(B13,'DSSV_ĐK_HƯỚNG ĐỀ TÀI'!$B$8:$O$208,2,0) -> Ngô Tuấn | L13: =VLOOKUP(B13,'DSSV_ĐK_HƯỚNG ĐỀ TÀI'!$B$8:$O$208,3,0) -> Thành
A14: 11 | B14: DH51902585 | C14: Trần Đình | D14: Hiền | E14: D19_TH07 | F14: CS03153 | G14: Đồ án / Khóa luận tốt nghiệp | H14: 0843999346 | I14: =B14&"@student.stu.edu.vn" -> DH51902585@student.stu.edu.vn | K14: =VLOOKUP(B14,'DSSV_ĐK_HƯỚNG ĐỀ TÀI'!$B$8:$O$208,2,0) -> Trần Đình | L14: =VLOOKUP(B14,'DSSV_ĐK_HƯỚNG ĐỀ TÀI'!$B$8:$O$208,3,0) -> Hiền
A15: 12 | B15: DH51902347 | C15: Trần Xuân | D15: Trí | E15: D19_TH08 | F15: CS03153 | G15: Đồ án / Khóa luận tốt nghiệp | H15: 0985711195 | I15: =B15&"@student.stu.edu.vn" -> DH51902347@student.stu.edu.vn | J15: Bổ sung | K15: =VLOOKUP(B15,'DSSV_ĐK_HƯỚNG ĐỀ TÀI'!$B$8:$O$208,2,0) -> Trần Xuân | L15: =VLOOKUP(B15,'DSSV_ĐK_HƯỚNG ĐỀ TÀI'!$B$8:$O$208,3,0) -> Trí
A16: 13 | B16: DH51905502 | C16: Châu Bảo Nhân | D16: Trung | E16: D19_TH09 | F16: CS03153 | G16: Đồ án / Khóa luận tốt nghiệp | H16: 0764332369 | I16: =B16&"@student.stu.edu.vn" -> DH51905502@student.stu.edu.vn | K16: =VLOOKUP(B16,'DSSV_ĐK_HƯỚNG ĐỀ TÀI'!$B$8:$O$208,2,0) -> Châu Bảo Nhân | L16: =VLOOKUP(B16,'DSSV_ĐK_HƯỚNG ĐỀ TÀI'!$B$8:$O$208,3,0) -> Trung
A17: 14 | B17: DH52002303 | C17: Lê Chí | D17: Cường | E17: D20_TH01 | F17: CS03153 | G17: Đồ án / Khóa luận tốt nghiệp | H17: 0904446653 | I17: =B17&"@student.stu.edu.vn" -> DH52002303@student.stu.edu.vn | K17: =VLOOKUP(B17,'DSSV_ĐK_HƯỚNG ĐỀ TÀI'!$B$8:$O$208,2,0) -> Lê Chí | L17: =VLOOKUP(B17,'DSSV_ĐK_HƯỚNG ĐỀ TÀI'!$B$8:$O$208,3,0) -> Cường
A18: 15 | B18: DH52000037 | C18: Đỗ Hoàng | D18: Dũng | E18: D20_TH01 | F18: CS03153 | G18: Đồ án / Khóa luận tốt nghiệp | H18: 0789140801 | I18: =B18&"@student.stu.edu.vn" -> DH52000037@student.stu.edu.vn | K18: =VLOOKUP(B18,'DSSV_ĐK_HƯỚNG ĐỀ TÀI'!$B$8:$O$208,2,0) -> Đỗ Hoàng | L18: =VLOOKUP(B18,'DSSV_ĐK_HƯỚNG ĐỀ TÀI'!$B$8:$O$208,3,0) -> Dũng
A19: 16 | B19: DH51901190 | C19: Trần Quốc | D19: Đạt | E19: D20_TH01 | F19: CS03153 | G19: Đồ án / Khóa luận tốt nghiệp | H19: 0706839897 | I19: =B19&"@student.stu.edu.vn" -> DH51901190@student.stu.edu.vn | K19: =VLOOKUP(B19,'DSSV_ĐK_HƯỚNG ĐỀ TÀI'!$B$8:$O$208,2,0) -> Trần Quốc | L19: =VLOOKUP(B19,'DSSV_ĐK_HƯỚNG ĐỀ TÀI'!$B$8:$O$208,3,0) -> Đạt
A20: 17 | B20: DH52001367 | C20: Lâm Chí | D20: Minh | E20: D20_TH01 | F20: CS03153 | G20: Đồ án / Khóa luận tốt nghiệp | H20: 0924405798 | I20: =B20&"@student.stu.edu.vn" -> DH52001367@student.stu.edu.vn | K20: =VLOOKUP(B20,'DSSV_ĐK_HƯỚNG ĐỀ TÀI'!$B$8:$O$208,2,0) -> Lâm Chí | L20: =VLOOKUP(B20,'DSSV_ĐK_HƯỚNG ĐỀ TÀI'!$B$8:$O$208,3,0) -> Minh
A21: 18 | B21: DH52002302 | C21: Cao Hoàng | D21: Nam | E21: D20_TH01 | F21: CS03153 | G21: Đồ án / Khóa luận tốt nghiệp | H21: 0909393047 | I21: =B21&"@student.stu.edu.vn" -> DH52002302@student.stu.edu.vn | K21: =VLOOKUP(B21,'DSSV_ĐK_HƯỚNG ĐỀ TÀI'!$B$8:$O$208,2,0) -> Cao Hoàng | L21: =VLOOKUP(B21,'DSSV_ĐK_HƯỚNG ĐỀ TÀI'!$B$8:$O$208,3,0) -> Nam
A22: 19 | B22: DH52003145 | C22: Huỳnh Trần Anh | D22: Quốc | E22: D20_TH01 | F22: CS03153 | G22: Đồ án / Khóa luận tốt nghiệp | H22: 0916823659 | I22: =B22&"@student.stu.edu.vn" -> DH52003145@student.stu.edu.vn | K22: =VLOOKUP(B22,'DSSV_ĐK_HƯỚNG ĐỀ TÀI'!$B$8:$O$208,2,0) -> Huỳnh Trần Anh | L22: =VLOOKUP(B22,'DSSV_ĐK_HƯỚNG ĐỀ TÀI'!$B$8:$O$208,3,0) -> Quốc
A23: 20 | B23: DH52001900 | C23: Nguyễn Minh | D23: Triều | E23: D20_TH01 | F23: CS03153 | G23: Đồ án / Khóa luận tốt nghiệp | H23: 0899052420 | I23: =B23&"@student.stu.edu.vn" -> DH52001900@student.stu.edu.vn | K23: =VLOOKUP(B23,'DSSV_ĐK_HƯỚNG ĐỀ TÀI'!$B$8:$O$208,2,0) -> Nguyễn Minh | L23: =VLOOKUP(B23,'DSSV_ĐK_HƯỚNG ĐỀ TÀI'!$B$8:$O$208,3,0) -> Triều
A24: 21 | B24: DH52001904 | C24: Nguyễn Hữu | D24: Trường | E24: D20_TH01 | F24: CS03153 | G24: Đồ án / Khóa luận tốt nghiệp | H24: 0855021202 | I24: =B24&"@student.stu.edu.vn" -> DH52001904@student.stu.edu.vn | K24: =VLOOKUP(B24,'DSSV_ĐK_HƯỚNG ĐỀ TÀI'!$B$8:$O$208,2,0) -> Nguyễn Hữu | L24: =VLOOKUP(B24,'DSSV_ĐK_HƯỚNG ĐỀ TÀI'!$B$8:$O$208,3,0) -> Trường
A25: 22 | B25: DH52001688 | C25: Phạm Nhựt | D25: Linh | E25: D20_TH02 | F25: CS03153 | G25: Đồ án / Khóa luận tốt nghiệp | H25: 0794985963 | I25: =B25&"@student.stu.edu.vn" -> DH52001688@student.stu.edu.vn | K25: =VLOOKUP(B25,'DSSV_ĐK_HƯỚNG ĐỀ TÀI'!$B$8:$O$208,2,0) -> Phạm Nhựt | L25: =VLOOKUP(B25,'DSSV_ĐK_HƯỚNG ĐỀ TÀI'!$B$8:$O$208,3,0) -> Linh
A26: 23 | B26: DH52003592 | C26: Nguyễn Khải | D26: Minh | E26: D20_TH02 | F26: CS03153 | G26: Đồ án / Khóa luận tốt nghiệp | H26: 0706908180 | I26: =B26&"@student.stu.edu.vn" -> DH52003592@student.stu.edu.vn | K26: =VLOOKUP(B26,'DSSV_ĐK_HƯỚNG ĐỀ TÀI'!$B$8:$O$208,2,0) -> Nguyễn Khải | L26: =VLOOKUP(B26,'DSSV_ĐK_HƯỚNG ĐỀ TÀI'!$B$8:$O$208,3,0) -> Minh
A27: 24 | B27: DH52001024 | C27: Nguyễn Duy | D27: Sơn | E27: D20_TH02 | F27: CS03153 | G27: Đồ án / Khóa luận tốt nghiệp | H27: 0783887570 | I27: =B27&"@student.stu.edu.vn" -> DH52001024@student.stu.edu.vn | K27: =VLOOKUP(B27,'DSSV_ĐK_HƯỚNG ĐỀ TÀI'!$B$8:$O$208,2,0) -> Nguyễn Duy | L27: =VLOOKUP(B27,'DSSV_ĐK_HƯỚNG ĐỀ TÀI'!$B$8:$O$208,3,0) -> Sơn
... A30: 27 | B30: DH52001330 | C30: Phạm Ngọc | D30: Đông | E30: D20_TH03 | F30: CS03153 | G30: Đồ án / Khóa luận tốt nghiệp | H30: 0366468307 | I30: =B30&"@student.stu.edu.vn" -> DH52001330@student.stu.edu.vn | K30: =VLOOKUP(B30,'DSSV_ĐK_HƯỚNG ĐỀ TÀI'!$B$8:$O$208,2,0) -> Phạm Ngọc | L30: =VLOOKUP(B30,'DSSV_ĐK_HƯỚNG ĐỀ TÀI'!$B$8:$O$208,3,0) -> Đông
A31: 28 | B31: DH52003489 | C31: Nguyễn Thanh | D31: Hải | E31: D20_TH03 | F31: CS03153 | G31: Đồ án / Khóa luận tốt nghiệp | H31: 0981665982 | I31: =B31&"@student.stu.edu.vn" -> DH52003489@student.stu.edu.vn | J31: Bổ sung | K31: =VLOOKUP(B31,'DSSV_ĐK_HƯỚNG ĐỀ TÀI'!$B$8:$O$208,2,0) -> Nguyễn Thanh | L31: =VLOOKUP(B31,'DSSV_ĐK_HƯỚNG ĐỀ TÀI'!$B$8:$O$208,3,0) -> Hải
A32: 29 | B32: DH52002187 | C32: Lê Văn | D32: Nam | E32: D20_TH03 | F32: CS03153 | G32: Đồ án / Khóa luận tốt nghiệp | H32: 0915513815 | I32: =B32&"@student.stu.edu.vn" -> DH52002187@student.stu.edu.vn | J32: Bổ sung | K32: =VLOOKUP(B32,'DSSV_ĐK_HƯỚNG ĐỀ TÀI'!$B$8:$O$208,2,0) -> Lê Văn | L32: =VLOOKUP(B32,'DSSV_ĐK_HƯỚNG ĐỀ TÀI'!$B$8:$O$208,3,0) -> Nam
A33: 30 | B33: DH52000682 | C33: Lê | D33: Tuấn | E33: D20_TH03 | F33: CS03153 | G33: Đồ án / Khóa luận tốt nghiệp | H33: 0777789336 | I33: =B33&"@student.stu.edu.vn" -> DH52000682@student.stu.edu.vn | K33: =VLOOKUP(B33,'DSSV_ĐK_HƯỚNG ĐỀ TÀI'!$B$8:$O$208,2,0) -> Lê | L33: =VLOOKUP(B33,'DSSV_ĐK_HƯỚNG ĐỀ TÀI'!$B$8:$O$208,3,0) -> Tuấn
A34: 31 | B34: DH52003563 | C34: Phan Văn | D34: Việt | E34: D20_TH03 | F34: CS03153 | G34: Đồ án / Khóa luận tốt nghiệp | H34: 0934487805 | I34: DH52003563@student.stu.edu.vn | J34: Rút đăng ký môn học | K34: =VLOOKUP(B34,'DSSV_ĐK_HƯỚNG ĐỀ TÀI'!$B$8:$O$208,2,0) -> #N/A | L34: =VLOOKUP(B34,'DSSV_ĐK_HƯỚNG ĐỀ TÀI'!$B$8:$O$208,3,0) -> #N/A
A35: 32 | B35: DH52002723 | C35: Phạm Ngọc | D35: Khoa | E35: D20_TH04 | F35: CS03153 | G35: Đồ án / Khóa luận tốt nghiệp | H35: 0528051699 | I35: =B35&"@student.stu.edu.vn" -> DH52002723@student.stu.edu.vn | K35: =VLOOKUP(B35,'DSSV_ĐK_HƯỚNG ĐỀ TÀI'!$B$8:$O$208,2,0) -> Phạm Ngọc | L35: =VLOOKUP(B35,'DSSV_ĐK_HƯỚNG ĐỀ TÀI'!$B$8:$O$208,3,0) -> Khoa
A36: 33 | B36: DH52003935 | C36: Phạm Châu | D36: Phú | E36: D20_TH04 | F36: CS03153 | G36: Đồ án / Khóa luận tốt nghiệp | H36: 0337847385 | I36: =B36&"@student.stu.edu.vn" -> DH52003935@student.stu.edu.vn | K36: =VLOOKUP(B36,'DSSV_ĐK_HƯỚNG ĐỀ TÀI'!$B$8:$O$208,2,0) -> Phạm Châu | L36: =VLOOKUP(B36,'DSSV_ĐK_HƯỚNG ĐỀ TÀI'!$B$8:$O$208,3,0) -> Phú
A37: 34 | B37: DH52003995 | C37: Huỳnh Thanh | D37: Phúc | E37: D20_TH04 | F37: CS03153 | G37: Đồ án / Khóa luận tốt nghiệp | H37: 0348095507 | I37: =B37&"@student.stu.edu.vn" -> DH52003995@student.stu.edu.vn | K37: =VLOOKUP(B37,'DSSV_ĐK_HƯỚNG ĐỀ TÀI'!$B$8:$O$208,2,0) -> Huỳnh Thanh | L37: =VLOOKUP(B37,'DSSV_ĐK_HƯỚNG ĐỀ TÀI'!$B$8:$O$208,3,0) -> Phúc
A38: 35 | B38: DH52001281 | C38: Phạm Tôn | D38: Thuận | E38: D20_TH04 | F38: CS03153 | G38: Đồ án / Khóa luận tốt nghiệp | H38: 0902827377 | I38: =B38&"@student.stu.edu.vn" -> DH52001281@student.stu.edu.vn | K38: =VLOOKUP(B38,'DSSV_ĐK_HƯỚNG ĐỀ TÀI'!$B$8:$O$208,2,0) -> Phạm Tôn | L38: =VLOOKUP(B38,'DSSV_ĐK_HƯỚNG ĐỀ TÀI'!$B$8:$O$208,3,0) -> Thuận
A39: 36 | B39: DH52003543 | C39: Nguyễn Công | D39: Chi | E39: D20_TH05 | F39: CS03153 | G39: Đồ án / Khóa luận tốt nghiệp | H39: 0523261143 | I39: =B39&"@student.stu.edu.vn" -> DH52003543@student.stu.edu.vn | K39: =VLOOKUP(B39,'DSSV_ĐK_HƯỚNG ĐỀ TÀI'!$B$8:$O$208,2,0) -> Nguyễn Công | L39: =VLOOKUP(B39,'DSSV_ĐK_HƯỚNG ĐỀ TÀI'!$B$8:$O$208,3,0) -> Chi
A40: 37 | B40: DH52001243 | C40: Lưu Văn | D40: Hiếu | E40: D20_TH05 | F40: CS03153 | G40: Đồ án / Khóa luận tốt nghiệp | H40: 0977833079 | I40: =B40&"@student.stu.edu.vn" -> DH52001243@student.stu.edu.vn | K40: =VLOOKUP(B40,'DSSV_ĐK_HƯỚNG ĐỀ TÀI'!$B$8:$O$208,2,0) -> Lưu Văn | L40: =VLOOKUP(B40,'DSSV_ĐK_HƯỚNG ĐỀ TÀI'!$B$8:$O$208,3,0) -> Hiếu
A41: 38 | B41: DH52002358 | C41: Vương Tiến | D41: Hùng | E41: D20_TH05 | F41: CS03153 | G41: Đồ án / Khóa luận tốt nghiệp | H41: 0968189572 | I41: =B41&"@student.stu.edu.vn" -> DH52002358@student.stu.edu.vn | K41: =VLOOKUP(B41,'DSSV_ĐK_HƯỚNG ĐỀ TÀI'!$B$8:$O$208,2,0) -> Vương Tiến | L41: =VLOOKUP(B41,'DSSV_ĐK_HƯỚNG ĐỀ TÀI'!$B$8:$O$208,3,0) -> Hùng
A42: 39 | B42: DH52003835 | C42: Trần Đình | D42: Khoa | E42: D20_TH05 | F42: CS03153 | G42: Đồ án / Khóa luận tốt nghiệp | H42: 0707035451 | I42: =B42&"@student.stu.edu.vn" -> DH52003835@student.stu.edu.vn | K42: =VLOOKUP(B42,'DSSV_ĐK_HƯỚNG ĐỀ TÀI'!$B$8:$O$208,2,0) -> Trần Đình | L42: =VLOOKUP(B42,'DSSV_ĐK_HƯỚNG ĐỀ TÀI'!$B$8:$O$208,3,0) -> Khoa
...
